[32m2024-02-12 12:03:34 +0100[0m - dagster - [34mDEBUG[0m - __ASSET_JOB_0 - 6a326509-16a0-46ee-8faa-67bef8aac54e - 1094784 - LOGS_CAPTURED - Started capturing logs in process (pid: 1094784).
[32m2024-02-12 12:03:34 +0100[0m - dagster - [34mDEBUG[0m - __ASSET_JOB_0 - 6a326509-16a0-46ee-8faa-67bef8aac54e - 1094784 - flood__forecast - STEP_START - Started execution of step "flood__forecast".
INFO:alembic.runtime.migration:Context impl SQLiteImpl.
INFO:alembic.runtime.migration:Will assume non-transactional DDL.
INFO:alembic.runtime.migration:Context impl SQLiteImpl.
INFO:alembic.runtime.migration:Will assume non-transactional DDL.
INFO:alembic.runtime.migration:Running stamp_revision  -> 46b412388816
[32m2024-02-12 12:03:35 +0100[0m - dagster - [34mINFO[0m - __ASSET_JOB_0 - 6a326509-16a0-46ee-8faa-67bef8aac54e - flood__forecast - Joined dataframe:                     number       time   step valid_time     dis24
latitude longitude                                               
-2.025   33.575          0 2024-02-12 1 days 2024-02-13  2.203125
         33.575          1 2024-02-12 1 days 2024-02-13  2.156250
         33.575          2 2024-02-12 1 days 2024-02-13  2.171875
         33.575          3 2024-02-12 1 days 2024-02-13  2.171875
         33.575          4 2024-02-12 1 days 2024-02-13  2.156250
[32m2024-02-12 12:03:35 +0100[0m - dagster - [34mINFO[0m - __ASSET_JOB_0 - 6a326509-16a0-46ee-8faa-67bef8aac54e - flood__forecast - Joined dataframe: number                  int64
time           datetime64[ns]
step          timedelta64[ns]
valid_time     datetime64[ns]
dis24                 float32
dtype: object
[32m2024-02-12 12:03:35 +0100[0m - dagster - [34mERROR[0m - [31m__ASSET_JOB_0 - 6a326509-16a0-46ee-8faa-67bef8aac54e - 1094784 - flood__forecast - STEP_FAILURE - Execution of step "flood__forecast" failed.

dagster._core.errors.DagsterExecutionStepExecutionError: Error occurred while executing op "flood__forecast"::

KeyError: 'latitude'

Stack Trace:
  File "/home/giltinde/.cache/pypoetry/virtualenvs/data-pipelines-M3b6C7Oo-py3.11/lib/python3.11/site-packages/dagster/_core/execution/plan/utils.py", line 54, in op_execution_error_boundary
    yield
  File "/home/giltinde/.cache/pypoetry/virtualenvs/data-pipelines-M3b6C7Oo-py3.11/lib/python3.11/site-packages/dagster/_utils/__init__.py", line 467, in iterate_with_context
    next_output = next(iterator)
                  ^^^^^^^^^^^^^^
  File "/home/giltinde/.cache/pypoetry/virtualenvs/data-pipelines-M3b6C7Oo-py3.11/lib/python3.11/site-packages/dagster/_core/execution/plan/compute_generator.py", line 131, in _coerce_op_compute_fn_to_iterator
    result = invoke_compute_fn(
             ^^^^^^^^^^^^^^^^^^
  File "/home/giltinde/.cache/pypoetry/virtualenvs/data-pipelines-M3b6C7Oo-py3.11/lib/python3.11/site-packages/dagster/_core/execution/plan/compute_generator.py", line 125, in invoke_compute_fn
    return fn(context, **args_to_pass) if context_arg_provided else fn(**args_to_pass)
           ^^^^^^^^^^^^^^^^^^^^^^^^^^^
  File "/home/giltinde/knowit/projects/openepi/data-pipelines/data_pipelines/assets/flood/discharge_new.py", line 226, in forecast
    forecast_df["latitude"] = forecast_df["latitude"].round(GLOFAS_PRECISION)
                              ~~~~~~~~~~~^^^^^^^^^^^^
  File "/home/giltinde/.cache/pypoetry/virtualenvs/data-pipelines-M3b6C7Oo-py3.11/lib/python3.11/site-packages/dask/dataframe/core.py", line 5050, in __getitem__
    meta = self._meta[_extract_meta(key)]
           ~~~~~~~~~~^^^^^^^^^^^^^^^^^^^^
  File "/home/giltinde/.cache/pypoetry/virtualenvs/data-pipelines-M3b6C7Oo-py3.11/lib/python3.11/site-packages/pandas/core/frame.py", line 4090, in __getitem__
    indexer = self.columns.get_loc(key)
              ^^^^^^^^^^^^^^^^^^^^^^^^^
  File "/home/giltinde/.cache/pypoetry/virtualenvs/data-pipelines-M3b6C7Oo-py3.11/lib/python3.11/site-packages/pandas/core/indexes/base.py", line 3809, in get_loc
    raise KeyError(key) from err

The above exception was caused by the following exception:
KeyError: 'latitude'

Stack Trace:
  File "/home/giltinde/.cache/pypoetry/virtualenvs/data-pipelines-M3b6C7Oo-py3.11/lib/python3.11/site-packages/pandas/core/indexes/base.py", line 3802, in get_loc
    return self._engine.get_loc(casted_key)
           ^^^^^^^^^^^^^^^^^^^^^^^^^^^^^^^^
  File "index.pyx", line 153, in pandas._libs.index.IndexEngine.get_loc
  File "index.pyx", line 182, in pandas._libs.index.IndexEngine.get_loc
  File "pandas/_libs/hashtable_class_helper.pxi", line 7081, in pandas._libs.hashtable.PyObjectHashTable.get_item
  File "pandas/_libs/hashtable_class_helper.pxi", line 7089, in pandas._libs.hashtable.PyObjectHashTable.get_item
[0m
